Traceback (most recent call last):
  File "/home/ludch/miniconda3/envs/jupyter_book/lib/python3.10/site-packages/jupyter_cache/executors/utils.py", line 51, in single_nb_execution
    executenb(
  File "/home/ludch/miniconda3/envs/jupyter_book/lib/python3.10/site-packages/nbclient/client.py", line 1085, in execute
    return NotebookClient(nb=nb, resources=resources, km=km, **kwargs).execute()
  File "/home/ludch/miniconda3/envs/jupyter_book/lib/python3.10/site-packages/nbclient/util.py", line 84, in wrapped
    return just_run(coro(*args, **kwargs))
  File "/home/ludch/miniconda3/envs/jupyter_book/lib/python3.10/site-packages/nbclient/util.py", line 62, in just_run
    return loop.run_until_complete(coro)
  File "/home/ludch/miniconda3/envs/jupyter_book/lib/python3.10/asyncio/base_events.py", line 641, in run_until_complete
    return future.result()
  File "/home/ludch/miniconda3/envs/jupyter_book/lib/python3.10/site-packages/nbclient/client.py", line 551, in async_execute
    await self.async_execute_cell(
  File "/home/ludch/miniconda3/envs/jupyter_book/lib/python3.10/site-packages/nbclient/client.py", line 846, in async_execute_cell
    self._check_raise_for_error(cell, exec_reply)
  File "/home/ludch/miniconda3/envs/jupyter_book/lib/python3.10/site-packages/nbclient/client.py", line 748, in _check_raise_for_error
    raise CellExecutionError.from_cell_and_msg(cell, exec_reply_content)
nbclient.exceptions.CellExecutionError: An error occurred while executing the following cell:
------------------
# Setup
%load_ext autoreload
%matplotlib nbagg
%autoreload 2
import numpy as np
import pandas as pd
import matplotlib as mpl
from PIL import Image # On charge Python Image Library
from matplotlib import pyplot as plt # On charge pyplot (un sous module de Matplotlib) et on le renomme plt
from matplotlib import cm
from scipy import ndimage
from scipy import interpolate
from scipy import signal

import gpxpy
import gpxpy.gpx
from geopy.distance import great_circle, vincenty

------------------

[0;31m---------------------------------------------------------------------------[0m
[0;31mModuleNotFoundError[0m                       Traceback (most recent call last)
Input [0;32mIn [1][0m, in [0;36m<module>[0;34m[0m
[1;32m     12[0m [38;5;28;01mfrom[39;00m [38;5;21;01mscipy[39;00m [38;5;28;01mimport[39;00m interpolate
[1;32m     13[0m [38;5;28;01mfrom[39;00m [38;5;21;01mscipy[39;00m [38;5;28;01mimport[39;00m signal
[0;32m---> 15[0m [38;5;28;01mimport[39;00m [38;5;21;01mgpxpy[39;00m
[1;32m     16[0m [38;5;28;01mimport[39;00m [38;5;21;01mgpxpy[39;00m[38;5;21;01m.[39;00m[38;5;21;01mgpx[39;00m
[1;32m     17[0m [38;5;28;01mfrom[39;00m [38;5;21;01mgeopy[39;00m[38;5;21;01m.[39;00m[38;5;21;01mdistance[39;00m [38;5;28;01mimport[39;00m great_circle, vincenty

[0;31mModuleNotFoundError[0m: No module named 'gpxpy'
ModuleNotFoundError: No module named 'gpxpy'

