Traceback (most recent call last):
  File "/home/ludch/miniconda3/envs/jupyter_book/lib/python3.10/site-packages/jupyter_cache/executors/utils.py", line 51, in single_nb_execution
    executenb(
  File "/home/ludch/miniconda3/envs/jupyter_book/lib/python3.10/site-packages/nbclient/client.py", line 1085, in execute
    return NotebookClient(nb=nb, resources=resources, km=km, **kwargs).execute()
  File "/home/ludch/miniconda3/envs/jupyter_book/lib/python3.10/site-packages/nbclient/util.py", line 84, in wrapped
    return just_run(coro(*args, **kwargs))
  File "/home/ludch/miniconda3/envs/jupyter_book/lib/python3.10/site-packages/nbclient/util.py", line 62, in just_run
    return loop.run_until_complete(coro)
  File "/home/ludch/miniconda3/envs/jupyter_book/lib/python3.10/asyncio/base_events.py", line 641, in run_until_complete
    return future.result()
  File "/home/ludch/miniconda3/envs/jupyter_book/lib/python3.10/site-packages/nbclient/client.py", line 551, in async_execute
    await self.async_execute_cell(
  File "/home/ludch/miniconda3/envs/jupyter_book/lib/python3.10/site-packages/nbclient/client.py", line 846, in async_execute_cell
    self._check_raise_for_error(cell, exec_reply)
  File "/home/ludch/miniconda3/envs/jupyter_book/lib/python3.10/site-packages/nbclient/client.py", line 748, in _check_raise_for_error
    raise CellExecutionError.from_cell_and_msg(cell, exec_reply_content)
nbclient.exceptions.CellExecutionError: An error occurred while executing the following cell:
------------------
im = np.array(Image.open(workdir + name))
fig, ax = plt.subplots()
ax.axis("off")
plt.imshow(im, cmap = cm.copper)
plt.colorbar()
plt.show()
------------------

[0;31m---------------------------------------------------------------------------[0m
[0;31mFileNotFoundError[0m                         Traceback (most recent call last)
Input [0;32mIn [3][0m, in [0;36m<module>[0;34m[0m
[0;32m----> 1[0m im [38;5;241m=[39m np[38;5;241m.[39marray([43mImage[49m[38;5;241;43m.[39;49m[43mopen[49m[43m([49m[43mworkdir[49m[43m [49m[38;5;241;43m+[39;49m[43m [49m[43mname[49m[43m)[49m)
[1;32m      2[0m fig, ax [38;5;241m=[39m plt[38;5;241m.[39msubplots()
[1;32m      3[0m ax[38;5;241m.[39maxis([38;5;124m"[39m[38;5;124moff[39m[38;5;124m"[39m)

File [0;32m~/miniconda3/envs/jupyter_book/lib/python3.10/site-packages/PIL/Image.py:2975[0m, in [0;36mopen[0;34m(fp, mode, formats)[0m
[1;32m   2972[0m     filename [38;5;241m=[39m fp
[1;32m   2974[0m [38;5;28;01mif[39;00m filename:
[0;32m-> 2975[0m     fp [38;5;241m=[39m [43mbuiltins[49m[38;5;241;43m.[39;49m[43mopen[49m[43m([49m[43mfilename[49m[43m,[49m[43m [49m[38;5;124;43m"[39;49m[38;5;124;43mrb[39;49m[38;5;124;43m"[39;49m[43m)[49m
[1;32m   2976[0m     exclusive_fp [38;5;241m=[39m [38;5;28;01mTrue[39;00m
[1;32m   2978[0m [38;5;28;01mtry[39;00m:

[0;31mFileNotFoundError[0m: [Errno 2] No such file or directory: './HSLA 340.jpg'
FileNotFoundError: [Errno 2] No such file or directory: './HSLA 340.jpg'

